Workbook

Sheet 2448 2025
A1: TIP DOC. | B1: NUM.DOC | C1: FECHA_MOV | D1: SUC. | E1: SUC. DET | F1: C_COSTO | G1: NOM_CCOSTO | H1: TIPO DCR. | I1: NUM_DCR | J1: CUENTA | K1: NOM_CUENTA | L1: NIT O C.C. | M1: NOMBRE TERCERO | N1: BASES_IMP | O1: DEBITOS | P1: CREDITOS | Q1: MOVIMIENTO | R1: USUARIO | S1: AÑO | T1: NIT O C.C. TERC | U1: NOMBRE TERC
A2: CO | B2: 6000001 | C2: 45665 | D2: 6 | E2: 6 | F2: 999 | G2: Default | J2: 24480512 | K2: Rte Ica Servicios Leguizamo | L2: 891200513 | M2: ALCALDIA MUNICIPAL DE PUERTO LEGUIZAMO | N2: 1350000 | O2: 0 | P2: 6750 | Q2: CONTABILIZACION PAGO ARRENDAMIENTO ENERO 2025 OFICINA COOTEP AGENCIA LEGUIZAMO A LA SEÑORA MARIA INES SANCHEZ GONZALEZ CC 26636874 | R2: NPIMEN | S2: 2025 | T2: 26636874 | U2: SANCHEZ GONZALEZ MARIA INES
A3: CO | B3: 3000007 | C3: 45665 | D3: 3 | E3: 3 | F3: 999 | G3: Default | J3: 24480505 | K3: ICA Compras Puerto Asis | L3: 891200461 | M3: MUNICIPIO DE PUERTO ASIS | N3: 97142.86 | O3: 0 | P3: 680 | Q3: COMPRA DE SUMINISTRO DE ASEO N° FE 12156 | R3: KGUERR | S3: 2025 | T3: 14839233 | U3: RAMOS ZUÑIGA OLIVER
A4: CO | B4: 1000029 | C4: 45666 | D4: 1 | E4: 2 | F4: 999 | G4: Default | J4: 24480518 | K4: RteIcaServiciosSibundoy | L4: 891201645 | M4: ALCALDIA MUNICIPAL SIBUNDOY | N4: 270000 | O4: 0 | P4: 2700 | Q4: PAGO FACTURA HSE41124 A HYDRA SOLUCIONES EMPRESARIALES INGENIERIA SAS NIT 900437268 POR SERVICIO SE INTERNET EN LA AGENCIA DE SIBUNDOY MES DE ENERO 2025 | R4: HPARRA | S4: 2025 | T4: 900437268 | U4: HYDRA SOLUCIONES EMPRESARIALES INGENIERIA SAS
A5: CO | B5: 1000025 | C5: 45666 | D5: 1 | E5: 4 | F5: 999 | G5: Default | J5: 24480510 | K5: Rte Ica Servicios Hormiga | L5: 800102912 | M5: ALCALDIA MUNICIPAL VALLE DEL GUAMUEZ | N5: 380000 | O5: 0 | P5: 2660 | Q5: PAGO FACTURA NETS49622 A NET ISP NIT 900502634 POR SERVICIO DE INTERNET DEDICADO CORPORATIVO 15 MBPS EN LA AGENCIA DE LA GORMIGA MES DE NOVIEMBRE 2024 | R5: HPARRA | S5: 2025 | T5: 900502634 | U5: NET I.S.P S.A.S
A6: CO | B6: 1000026 | C6: 45666 | D6: 1 | E6: 7 | F6: 999 | G6: Default | J6: 24480515 | K6: Rte Ica San Miguel Servicios | L6: 800252922 | M6: ALCALDIA MUNICIPAL DE SAN MIGUEL | N6: 380000 | O6: 0 | P6: 3040 | Q6: PAGO FACTURA NETS49624 A NET ISP NIT 900502634 POR SERVICIO DE INTERNET DEDICADO CORPORATIVO 15 MBPS EN LA AGENCIA DE LA DORADA MES DE NOVIEMBRE 2024 | R6: HPARRA | S6: 2025 | T6: 900502634 | U6: NET I.S.P S.A.S
A7: CO | B7: 1000024 | C7: 45666 | D7: 1 | E7: 3 | F7: 999 | G7: Default | J7: 24480506 | K7: ICA Servicios Puerto Asis | L7: 891200461 | M7: MUNICIPIO DE PUERTO ASIS | N7: 295210 | O7: 0 | P7: 2952 | Q7: PAGO FACTURA FEPA31010 A ISANET NIT 900593821 POR SERIVIOC DE INTERNET 100 MEGAS DE LA AGENCIA DE PTO ASIS MES DE FEBRERO 2025 | R7: HPARRA | S7: 2025 | T7: 900593821 | U7: ISA NETWORKS ISP S.A.S
A8: NA | B8: 4000034 | C8: 45666 | D8: 4 | E8: 4 | F8: 999 | G8: Default | J8: 24480510 | K8: Rte Ica Servicios Hormiga | L8: 800102912 | M8: ALCALDIA MUNICIPAL VALLE DEL GUAMUEZ | N8: 300000 | O8: 0 | P8: 1800 | Q8: CONT PAGO SERVICIO DE PUBLICIDAD RADIAL EN LA BOCADA DE PROYECCION STEREO MES DIC/2024 | R8: ASEGUR | S8: 2025 | T8: 18153926 | U8: LUCERO BASTIDAS MIGUEL ANGEL
A9: CO | B9: 1000030 | C9: 45666 | D9: 1 | E9: 1 | F9: 999 | G9: Default | J9: 24480501 | K9: Servicios | L9: 800102891 | M9: ALCALDIA DE MOCOA | N9: 480000 | O9: 0 | P9: 4800 | Q9: PAGO FACTURA HSMC 1221 HYDRA SOLUCIONES EMPRESARIALES INGENIERIA SAS NIT 900437268 POR SERVICIO DEI NTERNERT EN LA AGENCIA DE MOCOA MES DE ENERO 2025 | R9: HPARRA | S9: 2025 | T9: 900437268 | U9: HYDRA SOLUCIONES EMPRESARIALES INGENIERIA SAS
A10: CO | B10: 2000003 | C10: 45667 | D10: 2 | E10: 2 | F10: 999 | G10: Default | J10: 24480518 | K10: RteIcaServiciosSibundoy | L10: 891201645 | M10: ALCALDIA MUNICIPAL SIBUNDOY | N10: 155000 | O10: 0 | P10: 1550 | Q10: Contabilizacion para examenes laborales ingreso de Hernan Santiago Zambrano asesor de microcredito | R10: HBURBA | S10: 2025 | T10: 900219717 | U10: IPS PREVENIR SIBUNDOY1
A11: CO | B11: 3000013 | C11: 45670 | D11: 3 | E11: 3 | F11: 999 | G11: Default | J11: 24480506 | K11: ICA Servicios Puerto Asis | L11: 891200461 | M11: MUNICIPIO DE PUERTO ASIS | N11: 280000 | O11: 0 | P11: 2240 | Q11: PAGO DE SERVICIO DE PUBLICIDAD RADIAL N° FV2145 | R11: KGUERR | S11: 2025 | T11: 846002782 | U11: CORPORACION COMUNITARIA CULTURAL Y DEPORTIVA 3 FRONTERAS FM RADIO
A12: CO | B12: 1000061 | C12: 45672 | D12: 1 | E12: 3 | F12: 999 | G12: Default | J12: 24480506 | K12: ICA Servicios Puerto Asis | L12: 891200461 | M12: MUNICIPIO DE PUERTO ASIS | N12: 0 | O12: 20628 | P12: 0 | Q12: PAGO A ALCALDIA DEL MUNICIPIO DE PUERTO ASIS NIT 891200461 RETENCION DE INDUSTRIA Y COMERCIO MES DE DICIEMBRE 2024 | R12: HPARRA | S12: 2025 | T12: 891200461 | U12: MUNICIPIO DE PUERTO ASIS
A13: CO | B13: 1000065 | C13: 45672 | D13: 1 | E13: 7 | F13: 999 | G13: Default | J13: 24480516 | K13: RteIca SanMiguel Compras | L13: 800252922 | M13: ALCALDIA MUNICIPAL DE SAN MIGUEL | N13: 0 | O13: 56051 | P13: 0 | Q13: PAGO A ALCALDIA DEL MUNICIPIO DE LA DORADA NIT 800252922 RETENCION DE INDUSTRIA Y COMERCIO MES DE DICIEMBRE 2024 | R13: HPARRA | S13: 2025 | T13: 800252922 | U13: ALCALDIA MUNICIPAL DE SAN MIGUEL
... A61: CO | B61: 1000292 | C61: 45702 | D61: 1 | E61: 3 | F61: 999 | G61: Default | J61: 24480506 | K61: ICA Servicios Puerto Asis | L61: 891200461 | M61: MUNICIPIO DE PUERTO ASIS | N61: 0 | O61: 5595 | P61: 0 | Q61: PAGO A ALCALDIA DE PTO ASISI POR RETENCION DE INDUSTRIA Y COMERCIO RETEICA MES DE ENERO 2025 | R61: HPARRA | S61: 2025 | T61: 891200461 | U61: MUNICIPIO DE PUERTO ASIS
A62: CO | B62: 1000295 | C62: 45702 | D62: 1 | E62: 7 | F62: 999 | G62: Default | J62: 24480515 | K62: Rte Ica San Miguel Servicios | L62: 800252922 | M62: ALCALDIA MUNICIPAL DE SAN MIGUEL | N62: 0 | O62: 9480 | P62: 0 | Q62: PAGO A ALCALDIA DE LA DORADA POR RETENCION DE INDUSTRIA Y COMERCIO RETEICA MES DE ENERO 2025
A63: CO | B63: 1000295 | C63: 45702 | D63: 1 | E63: 7 | F63: 999 | G63: Default | J63: 24480516 | K63: RteIca SanMiguel Compras | L63: 800252922 | M63: ALCALDIA MUNICIPAL DE SAN MIGUEL | N63: 0 | O63: 4480 | P63: 0 | Q63: PAGO A ALCALDIA DE LA DORADA POR RETENCION DE INDUSTRIA Y COMERCIO RETEICA MES DE ENERO 2025
A64: CO | B64: 1000294 | C64: 45702 | D64: 1 | E64: 6 | F64: 999 | G64: Default | J64: 24480512 | K64: Rte Ica Servicios Leguizamo | L64: 891200513 | M64: ALCALDIA MUNICIPAL DE PUERTO LEGUIZAMO | N64: 0 | O64: 6750 | P64: 0 | Q64: PAGO A ALCALDIA DE PTO LEGUIZAMO POR RETENCION DE INDUSTRIA Y COMERCIO RETEICA MES DE ENERO 2025 | R64: HPARRA | S64: 2025 | T64: 891200513 | U64: ALCALDIA MUNICIPAL DE PUERTO LEGUIZAMO
A65: CO | B65: 1000296 | C65: 45702 | D65: 1 | E65: 8 | F65: 999 | G65: Default | J65: 24480519 | K65: Servicios Villagarzón | L65: 800054249 | M65: ALCALDIA DE VILLAGARZON | N65: 0 | O65: 51519 | P65: 0 | Q65: PAGO A ALCALDIA DE LA DORADA POR RETENCION DE INDUSTRIA Y COMERCIO RETEICA MES DE ENERO 2025 | R65: HPARRA | S65: 2025 | T65: 800054249 | U65: ALCALDIA DE VILLAGARZON
A66: CO | B66: 1000290 | C66: 45702 | D66: 1 | E66: 1 | F66: 999 | G66: Default | J66: 24480502 | K66: Compras | L66: 800102891 | M66: ALCALDIA DE MOCOA | N66: 0 | O66: 65160 | P66: 0 | Q66: PAGO A ALCALDIA DE MOCOA POR RETENCION DE INDUSTRIA Y COMERCIO RETEICA MES DE ENERO 2025 | R66: HPARRA | S66: 2025 | T66: 800102891 | U66: ALCALDIA DE MOCOA
A67: CO | B67: 1000293 | C67: 45702 | D67: 1 | E67: 4 | F67: 999 | G67: Default | J67: 24480509 | K67: Rte Ica Compras Hormiga | L67: 800102912 | M67: ALCALDIA MUNICIPAL VALLE DEL GUAMUEZ | N67: 0 | O67: 920 | P67: 0 | Q67: PAGO A ALCALDIA DE VALLE DEL GUAMEZ POR RETENCION DE INDUSTRIA Y COMERCIO RETEICA MES DE ENERO 2025 | R67: HPARRA | S67: 2025 | T67: 800102912 | U67: ALCALDIA MUNICIPAL VALLE DEL GUAMUEZ
A68: CO | B68: 1000290 | C68: 45702 | D68: 1 | E68: 1 | F68: 999 | G68: Default | J68: 24480501 | K68: Servicios | L68: 800102891 | M68: ALCALDIA DE MOCOA | N68: 0 | O68: 82448 | P68: 0 | Q68: PAGO A ALCALDIA DE MOCOA POR RETENCION DE INDUSTRIA Y COMERCIO RETEICA MES DE ENERO 2025 | R68: HPARRA | S68: 2025 | T68: 800102891 | U68: ALCALDIA DE MOCOA
A69: CO | B69: 1000291 | C69: 45702 | D69: 1 | E69: 2 | F69: 999 | G69: Default | J69: 24480518 | K69: RteIcaServiciosSibundoy | L69: 891201645 | M69: ALCALDIA MUNICIPAL SIBUNDOY | N69: 0 | O69: 4250 | P69: 0 | Q69: PAGO A ALCALDIA DE SIBUNDOY POR RETENCION DE INDUSTRIA Y COMERCIO RETEICA MES DE ENERO 2025 | R69: HPARRA | S69: 2025 | T69: 891201645 | U69: ALCALDIA MUNICIPAL SIBUNDOY
A70: CO | B70: 1000292 | C70: 45702 | D70: 1 | E70: 3 | F70: 999 | G70: Default | J70: 24480505 | K70: ICA Compras Puerto Asis | L70: 891200461 | M70: MUNICIPIO DE PUERTO ASIS | N70: 0 | O70: 3223.51 | P70: 0 | Q70: PAGO A ALCALDIA DE PTO ASISI POR RETENCION DE INDUSTRIA Y COMERCIO RETEICA MES DE ENERO 2025 | R70: HPARRA | S70: 2025 | T70: 891200461 | U70: MUNICIPIO DE PUERTO ASIS
A71: CO | B71: 1000293 | C71: 45702 | D71: 1 | E71: 4 | F71: 999 | G71: Default | J71: 24480510 | K71: Rte Ica Servicios Hormiga | L71: 800102912 | M71: ALCALDIA MUNICIPAL VALLE DEL GUAMUEZ | N71: 0 | O71: 5780 | P71: 0 | Q71: PAGO A ALCALDIA DE VALLE DEL GUAMEZ POR RETENCION DE INDUSTRIA Y COMERCIO RETEICA MES DE ENERO 2025 | R71: HPARRA | S71: 2025 | T71: 800102912 | U71: ALCALDIA MUNICIPAL VALLE DEL GUAMUEZ
A72: CO | B72: 1000310 | C72: 45705 | D72: 1 | E72: 8 | F72: 999 | G72: Default | J72: 24480519 | K72: Servicios Villagarzón | L72: 800054249 | M72: ALCALDIA DE VILLAGARZON | N72: 10303705 | O72: 0 | P72: 51518 | Q72: PAGO DE FACTURA SERF 597 A SERLOGYC NIT 900579315 POR SERVICIO DE CORRESPONSALIA MUNICIPIO DE VILLAGARZON MES DE FEBRERO 2025 | R72: HPARRA | S72: 2025 | T72: 900579315 | U72: SERVICIOS LOGISTICA Y COMERCIALIZACION SOCIEDAD POR ACCIONES SIMPLIFICADA
A73: CO | B73: 3000063 | C73: 45705 | D73: 3 | E73: 3 | F73: 999 | G73: Default | J73: 24480506 | K73: ICA Servicios Puerto Asis | L73: 891200461 | M73: MUNICIPIO DE PUERTO ASIS | N73: 320000 | O73: 0 | P73: 2560 | Q73: PAGO SERVICIO DE PAUTAS PUBLICITARIAS DEL 12 ENERO AL 11 FEBRERO FRA FVE-195 | R73: CGAVIR | S73: 2025 | T73: 846002782 | U73: CORPORACION COMUNITARIA CULTURAL Y DEPORTIVA 3 FRONTERAS FM RADIO
A74: CO | B74: 1000314 | C74: 45706 | D74: 1 | E74: 4 | F74: 999 | G74: Default | J74: 24480510 | K74: Rte Ica Servicios Hormiga | L74: 800102912 | M74: ALCALDIA MUNICIPAL VALLE DEL GUAMUEZ | N74: 376050 | O74: 0 | P74: 2632 | Q74: PAGO FACTURA HO77757 A NOVACOMTIC NIT 900620983 POR SERVICIO DEI NTERNET STAR 40GM MES DE FEBRERO 2025 EN LA AGENCIA DE PTO LEGUIZAMO | R74: HPARRA | S74: 2025 | T74: 900620983 | U74: NOVACOM TIC S.A.S
A75: NA | B75: 1000697 | C75: 45712 | D75: 1 | E75: 1 | F75: 999 | G75: Default | J75: 24480501 | K75: Servicios | L75: 800102891 | M75: ALCALDIA DE MOCOA | N75: 1964075 | O75: 0 | P75: 19640 | Q75: PAGO FACTURA FE-651 A ZAMBRANO DUARTE NELSON FABIO CC 18127828 POR SERVICIO DE MONITOREO DE ALARMAS Y CAMARAS DE VIGILANCIA MES FEBRERO 2025 | R75: ANARVA | S75: 2025 | T75: 18127828 | U75: ZAMBRANO DUARTE NELSON FABIO
... A440: CO | B440: 4000448 | C440: 45979 | D440: 4 | E440: 4 | F440: 999 | G440: Default | J440: 24480510 | K440: Rte Ica Servicios Hormiga | L440: 800102912 | M440: ALCALDIA MUNICIPAL VALLE DEL GUAMUEZ | N440: 2402000 | O440: 0 | P440: 16814 | Q440: cont pago servicio de isntalacion de pvc, agencia la Hormiga, se hace descuentode ley reteica | R440: ASEGUR | S440: 2025 | T440: 83226508 | U440: BERMUDES BERMUDES OMAR
A441: CO | B441: 1002600 | C441: 45979 | D441: 1 | E441: 5 | F441: 999 | G441: Default | J441: 24480507 | K441: Rte Ica Compras Orito | L441: 800102896 | M441: ALCALDIA MUNICIPAL ORITO | N441: 0 | O441: 6050 | P441: 0 | Q441: PAGO A ALCALDIA DE ORITO NIT 800102896 POR RETENCION MENSUAL DE INDUSTRIA Y COMERCIO Y/O RTE. ICA MES OCTUBRE AÑO 2025
A442: CO | B442: 1002602 | C442: 45979 | D442: 1 | E442: 7 | F442: 999 | G442: Default | J442: 24480515 | K442: Rte Ica San Miguel Servicios | L442: 800252922 | M442: ALCALDIA MUNICIPAL DE SAN MIGUEL | N442: 0 | O442: 48253 | P442: 0 | Q442: PAGO A ALCALDIA DE SAN MIGUEL NIT 800252922 POR RETENCION MENSUAL DE INDUSTRIA Y COMERCIO Y/O RTE. ICA MES OCTUBRE AÑO 2025
A443: CO | B443: 1002599 | C443: 45979 | D443: 1 | E443: 4 | F443: 999 | G443: Default | J443: 24480509 | K443: Rte Ica Compras Hormiga | L443: 800102912 | M443: ALCALDIA MUNICIPAL VALLE DEL GUAMUEZ | N443: 0 | O443: 282457 | P443: 0 | Q443: PAGO A ALCALDIA DE VALLE DEL GUAMEZ NIT 800102912 POR RETENCION MENSUAL DE INDUSTRIA Y COMERCIO Y/O RTE. ICA MES OCTUBRE AÑO 2025
A444: CO | B444: 1002604 | C444: 45979 | D444: 1 | E444: 8 | F444: 999 | G444: Default | J444: 24480519 | K444: Servicios Villagarzón | L444: 800054249 | M444: ALCALDIA DE VILLAGARZON | N444: 0 | O444: 56047 | P444: 0 | Q444: PAGO A ALCALDIA DE VILLA GARZON NIT 800054249 POR RETENCION MENSUAL DE INDUSTRIA Y COMERCIO Y/O RTE. ICA MES OCTUBRE AÑO 2025
A445: CO | B445: 1002601 | C445: 45979 | D445: 1 | E445: 6 | F445: 999 | G445: Default | J445: 24480512 | K445: Rte Ica Servicios Leguizamo | L445: 891200513 | M445: ALCALDIA MUNICIPAL DE PUERTO LEGUIZAMO | N445: 0 | O445: 14202 | P445: 0 | Q445: PAGO A ALCALDIA DE PUERTO LEGUIZAMO NIT 891200513 POR RETENCION MENSUAL DE INDUSTRIA Y COMERCIO Y/O RTE. ICA MES OCTUBRE AÑO 2025
A446: CO | B446: 1002598 | C446: 45979 | D446: 1 | E446: 3 | F446: 999 | G446: Default | J446: 24480506 | K446: ICA Servicios Puerto Asis | L446: 891200461 | M446: MUNICIPIO DE PUERTO ASIS | N446: 0 | O446: 13000 | P446: 0 | Q446: PAGO A ALCALDIA DE PUERTO ASIS NIT 891200461 POR RETENCION MENSUAL DE INDUSTRIA Y COMERCIO Y/O RTE. ICA MES OCTUBRE AÑO 2025
A447: CO | B447: 1002596 | C447: 45979 | D447: 1 | E447: 1 | F447: 999 | G447: Default | J447: 24480502 | K447: Compras | L447: 800102891 | M447: ALCALDIA DE MOCOA | N447: 0 | O447: 16800 | P447: 0 | Q447: PAGO A ALCALDIA DE MOCOA NIT 800102891 POR RETENCION MENSUAL DE INDUSTRIA Y COMERCIO Y/O RTE. ICA MES OCTUBRE AÑO 2025 | R447: HPARRA | S447: 2025 | T447: 800102891 | U447: ALCALDIA DE MOCOA
A448: CO | B448: 1002600 | C448: 45979 | D448: 1 | E448: 5 | F448: 999 | G448: Default | J448: 24480508 | K448: Rte Ica Servicios Orito | L448: 800102896 | M448: ALCALDIA MUNICIPAL ORITO | N448: 0 | O448: 17000 | P448: 0 | Q448: PAGO A ALCALDIA DE ORITO NIT 800102896 POR RETENCION MENSUAL DE INDUSTRIA Y COMERCIO Y/O RTE. ICA MES OCTUBRE AÑO 2025
A449: CO | B449: 1002597 | C449: 45979 | D449: 1 | E449: 2 | F449: 999 | G449: Default | J449: 24480518 | K449: RteIcaServiciosSibundoy | L449: 891201645 | M449: ALCALDIA MUNICIPAL SIBUNDOY | N449: 0 | O449: 38700 | P449: 0 | Q449: PAGO A ALCALDIA DE SIBUNDOY NIT 891201645 POR RETENCION MENSUAL DE INDUSTRIA Y COMERCIO Y/O RTE. ICA MES OCTUBRE AÑO 2025
A450: CO | B450: 1002599 | C450: 45979 | D450: 1 | E450: 4 | F450: 999 | G450: Default | J450: 24480510 | K450: Rte Ica Servicios Hormiga | L450: 800102912 | M450: ALCALDIA MUNICIPAL VALLE DEL GUAMUEZ | N450: 0 | O450: 42606 | P450: 0 | Q450: PAGO A ALCALDIA DE VALLE DEL GUAMEZ NIT 800102912 POR RETENCION MENSUAL DE INDUSTRIA Y COMERCIO Y/O RTE. ICA MES OCTUBRE AÑO 2025
A451: CO | B451: 4000452 | C451: 45981 | D451: 4 | E451: 4 | F451: 999 | G451: Default | J451: 24480509 | K451: Rte Ica Compras Hormiga | L451: 800102912 | M451: ALCALDIA MUNICIPAL VALLE DEL GUAMUEZ | N451: 200000 | O451: 0 | P451: 1400 | Q451: CONT PAGO DE ARENA Y TAMIZADO, PARA ADECUACION DE PSIO, ANDEN COOTEP AEGNCIA LA HORMIGA. | R451: ASEGUR | S451: 2025 | T451: 18155317 | U451: NASTACUAS CUARAN MILTON JAVIER
...

Sheet MOCOAA
E2: COMPRAS | G2: SERVICIOS
A3: Etiquetas de fila | B3: Suma de CREDITOS | E3: BASE | F3: RETENCION | G3: BASE | H3: RETENCION
A4: 5348917 | B4: 72500 | C4: =+A4 -> 5348917 | D4: =+VLOOKUP(C4,mocoa!T:U,2,0) -> PARDO VALENCIA CARLOS HERNANDO | E4: =+SUMIFS(mocoa!N:N,mocoa!K:K,MOCOAA!$E$2,mocoa!T:T,MOCOAA!C4) -> 0 | F4: =+SUMIFS(mocoa!P:P,mocoa!K:K,MOCOAA!$E$2,mocoa!T:T,MOCOAA!C4) -> 0 | G4: =+SUMIFS(mocoa!N:N,mocoa!K:K,MOCOAA!$G$2,mocoa!T:T,MOCOAA!C4) -> 7250000 | H4: =+SUMIFS(mocoa!P:P,mocoa!K:K,MOCOAA!$G$2,mocoa!T:T,MOCOAA!C4) -> 72500
A5: 12997019 | B5: 20000 | C5: =+A5 -> 12997019 | D5: =+VLOOKUP(C5,mocoa!T:U,2,0) -> PATIÑO ALPALA LUIS CAMILO | E5: =+SUMIFS(mocoa!N:N,mocoa!K:K,MOCOAA!$E$2,mocoa!T:T,MOCOAA!C5) -> 0 | F5: =+SUMIFS(mocoa!P:P,mocoa!K:K,MOCOAA!$E$2,mocoa!T:T,MOCOAA!C5) -> 0 | G5: =+SUMIFS(mocoa!N:N,mocoa!K:K,MOCOAA!$G$2,mocoa!T:T,MOCOAA!C5) -> 2000000 | H5: =+SUMIFS(mocoa!P:P,mocoa!K:K,MOCOAA!$G$2,mocoa!T:T,MOCOAA!C5) -> 20000
A6: 17655791 | B6: 4176 | C6: =+A6 -> 17655791 | D6: =+VLOOKUP(C6,mocoa!T:U,2,0) -> REINOSO CASTILLO WILLYE JAVIER | E6: =+SUMIFS(mocoa!N:N,mocoa!K:K,MOCOAA!$E$2,mocoa!T:T,MOCOAA!C6) -> 696000 | F6: =+SUMIFS(mocoa!P:P,mocoa!K:K,MOCOAA!$E$2,mocoa!T:T,MOCOAA!C6) -> 4176 | G6: =+SUMIFS(mocoa!N:N,mocoa!K:K,MOCOAA!$G$2,mocoa!T:T,MOCOAA!C6) -> 0 | H6: =+SUMIFS(mocoa!P:P,mocoa!K:K,MOCOAA!$G$2,mocoa!T:T,MOCOAA!C6) -> 0
A7: 18125023 | B7: 8011 | C7: =+A7 -> 18125023 | D7: =+VLOOKUP(C7,mocoa!T:U,2,0) -> ERAZO ACOSTA LUIS ALEJANDRO | E7: =+SUMIFS(mocoa!N:N,mocoa!K:K,MOCOAA!$E$2,mocoa!T:T,MOCOAA!C7) -> 1335231 | F7: =+SUMIFS(mocoa!P:P,mocoa!K:K,MOCOAA!$E$2,mocoa!T:T,MOCOAA!C7) -> 8011 | G7: =+SUMIFS(mocoa!N:N,mocoa!K:K,MOCOAA!$G$2,mocoa!T:T,MOCOAA!C7) -> 0 | H7: =+SUMIFS(mocoa!P:P,mocoa!K:K,MOCOAA!$G$2,mocoa!T:T,MOCOAA!C7) -> 0
A8: 18125303 | B8: 5165 | C8: =+A8 -> 18125303 | D8: =+VLOOKUP(C8,mocoa!T:U,2,0) -> GORDILLO GUZMAN ALIPIO | E8: =+SUMIFS(mocoa!N:N,mocoa!K:K,MOCOAA!$E$2,mocoa!T:T,MOCOAA!C8) -> 0 | F8: =+SUMIFS(mocoa!P:P,mocoa!K:K,MOCOAA!$E$2,mocoa!T:T,MOCOAA!C8) -> 0 | G8: =+SUMIFS(mocoa!N:N,mocoa!K:K,MOCOAA!$G$2,mocoa!T:T,MOCOAA!C8) -> 516500 | H8: =+SUMIFS(mocoa!P:P,mocoa!K:K,MOCOAA!$G$2,mocoa!T:T,MOCOAA!C8) -> 5165
A9: 18126274 | B9: 6500 | C9: =+A9 -> 18126274 | D9: =+VLOOKUP(C9,mocoa!T:U,2,0) -> ALVAREZ RUIZ GERMAN | E9: =+SUMIFS(mocoa!N:N,mocoa!K:K,MOCOAA!$E$2,mocoa!T:T,MOCOAA!C9) -> 0 | F9: =+SUMIFS(mocoa!P:P,mocoa!K:K,MOCOAA!$E$2,mocoa!T:T,MOCOAA!C9) -> 0 | G9: =+SUMIFS(mocoa!N:N,mocoa!K:K,MOCOAA!$G$2,mocoa!T:T,MOCOAA!C9) -> 650000 | H9: =+SUMIFS(mocoa!P:P,mocoa!K:K,MOCOAA!$G$2,mocoa!T:T,MOCOAA!C9) -> 6500
A10: 18126542 | B10: 13200 | C10: =+A10 -> 18126542 | D10: =+VLOOKUP(C10,mocoa!T:U,2,0) -> IMBACHI BENAVIDES EDINSON | E10: =+SUMIFS(mocoa!N:N,mocoa!K:K,MOCOAA!$E$2,mocoa!T:T,MOCOAA!C10) -> 0 | F10: =+SUMIFS(mocoa!P:P,mocoa!K:K,MOCOAA!$E$2,mocoa!T:T,MOCOAA!C10) -> 0 | G10: =+SUMIFS(mocoa!N:N,mocoa!K:K,MOCOAA!$G$2,mocoa!T:T,MOCOAA!C10) -> 1320000 | H10: =+SUMIFS(mocoa!P:P,mocoa!K:K,MOCOAA!$G$2,mocoa!T:T,MOCOAA!C10) -> 13200
A11: 18127030 | B11: 4632 | C11: =+A11 -> 18127030 | D11: =+VLOOKUP(C11,mocoa!T:U,2,0) -> ROSERO MONCAYO YESID BERNARDO | E11: =+SUMIFS(mocoa!N:N,mocoa!K:K,MOCOAA!$E$2,mocoa!T:T,MOCOAA!C11) -> 772000 | F11: =+SUMIFS(mocoa!P:P,mocoa!K:K,MOCOAA!$E$2,mocoa!T:T,MOCOAA!C11) -> 4632 | G11: =+SUMIFS(mocoa!N:N,mocoa!K:K,MOCOAA!$G$2,mocoa!T:T,MOCOAA!C11) -> 0 | H11: =+SUMIFS(mocoa!P:P,mocoa!K:K,MOCOAA!$G$2,mocoa!T:T,MOCOAA!C11) -> 0
A12: 18127050 | B12: 2000 | C12: =+A12 -> 18127050 | D12: =+VLOOKUP(C12,mocoa!T:U,2,0) -> MUÑOZ CERON GIOVANNY | E12: =+SUMIFS(mocoa!N:N,mocoa!K:K,MOCOAA!$E$2,mocoa!T:T,MOCOAA!C12) -> 0 | F12: =+SUMIFS(mocoa!P:P,mocoa!K:K,MOCOAA!$E$2,mocoa!T:T,MOCOAA!C12) -> 0 | G12: =+SUMIFS(mocoa!N:N,mocoa!K:K,MOCOAA!$G$2,mocoa!T:T,MOCOAA!C12) -> 200000 | H12: =+SUMIFS(mocoa!P:P,mocoa!K:K,MOCOAA!$G$2,mocoa!T:T,MOCOAA!C12) -> 2000
A13: 18127828 | B13: 212510 | C13: =+A13 -> 18127828 | D13: =+VLOOKUP(C13,mocoa!T:U,2,0) -> ZAMBRANO DUARTE NELSON FABIO | E13: =+SUMIFS(mocoa!N:N,mocoa!K:K,MOCOAA!$E$2,mocoa!T:T,MOCOAA!C13) -> 0 | F13: =+SUMIFS(mocoa!P:P,mocoa!K:K,MOCOAA!$E$2,mocoa!T:T,MOCOAA!C13) -> 0 | G13: =+SUMIFS(mocoa!N:N,mocoa!K:K,MOCOAA!$G$2,mocoa!T:T,MOCOAA!C13) -> 21250939 | H13: =+SUMIFS(mocoa!P:P,mocoa!K:K,MOCOAA!$G$2,mocoa!T:T,MOCOAA!C13) -> 212510
A14: 18130206 | B14: 22000 | C14: =+A14 -> 18130206 | D14: =+VLOOKUP(C14,mocoa!T:U,2,0) -> PORTILLA CERON JAIME | E14: =+SUMIFS(mocoa!N:N,mocoa!K:K,MOCOAA!$E$2,mocoa!T:T,MOCOAA!C14) -> 0 | F14: =+SUMIFS(mocoa!P:P,mocoa!K:K,MOCOAA!$E$2,mocoa!T:T,MOCOAA!C14) -> 0 | G14: =+SUMIFS(mocoa!N:N,mocoa!K:K,MOCOAA!$G$2,mocoa!T:T,MOCOAA!C14) -> 2200000 | H14: =+SUMIFS(mocoa!P:P,mocoa!K:K,MOCOAA!$G$2,mocoa!T:T,MOCOAA!C14) -> 22000
A15: 18145427 | B15: 791376 | C15: =+A15 -> 18145427 | D15: =+VLOOKUP(C15,mocoa!T:U,2,0) -> URQUIJO CHAVEZ DUCARDO JEMBER | E15: =+SUMIFS(mocoa!N:N,mocoa!K:K,MOCOAA!$E$2,mocoa!T:T,MOCOAA!C15) -> 0 | F15: =+SUMIFS(mocoa!P:P,mocoa!K:K,MOCOAA!$E$2,mocoa!T:T,MOCOAA!C15) -> 0 | G15: =+SUMIFS(mocoa!N:N,mocoa!K:K,MOCOAA!$G$2,mocoa!T:T,MOCOAA!C15) -> 79137636 | H15: =+SUMIFS(mocoa!P:P,mocoa!K:K,MOCOAA!$G$2,mocoa!T:T,MOCOAA!C15) -> 791376
... A46: 1126003236 | B46: 48283 | C46: =+A46 -> 1126003236 | D46: =+VLOOKUP(C46,mocoa!T:U,2,0) -> BERMEO MUSTAFA ALIA SAMADI | E46: =+SUMIFS(mocoa!N:N,mocoa!K:K,MOCOAA!$E$2,mocoa!T:T,MOCOAA!C46) -> 0 | F46: =+SUMIFS(mocoa!P:P,mocoa!K:K,MOCOAA!$E$2,mocoa!T:T,MOCOAA!C46) -> 0 | G46: =+SUMIFS(mocoa!N:N,mocoa!K:K,MOCOAA!$G$2,mocoa!T:T,MOCOAA!C46) -> 4828250 | H46: =+SUMIFS(mocoa!P:P,mocoa!K:K,MOCOAA!$G$2,mocoa!T:T,MOCOAA!C46) -> 48283
A47: Total general | B47: 1854238 | E47: =+SUMIFS(mocoa!N:N,mocoa!K:K,MOCOAA!$E$2,mocoa!T:T,MOCOAA!C47) -> 0 | F47: =+SUMIFS(mocoa!P:P,mocoa!K:K,MOCOAA!$E$2,mocoa!T:T,MOCOAA!C47) -> 0 | G47: =+SUMIFS(mocoa!N:N,mocoa!K:K,MOCOAA!$G$2,mocoa!T:T,MOCOAA!C47) -> 0 | H47: =+SUMIFS(mocoa!P:P,mocoa!K:K,MOCOAA!$G$2,mocoa!T:T,MOCOAA!C47) -> 0

Sheet mocoa
A1: TIP DOC. | B1: NUM.DOC | C1: FECHA_MOV | D1: SUC. | E1: SUC. DET | F1: C_COSTO | G1: NOM_CCOSTO | H1: TIPO DCR. | I1: NUM_DCR | J1: CUENTA | K1: NOM_CUENTA | L1: NIT O C.C. | M1: NOMBRE TERCERO | N1: BASES_IMP | O1: DEBITOS | P1: CREDITOS | Q1: MOVIMIENTO | R1: USUARIO | S1: AÑO | T1: NIT O C.C. TERC | U1: NOMBRE TERC
A2: CO | B2: 1000030 | C2: 45666 | D2: 1 | E2: 1 | F2: 999 | G2: Default | J2: 24480501 | K2: Servicios | L2: 800102891 | M2: ALCALDIA DE MOCOA | N2: 480000 | O2: 0 | P2: 4800 | Q2: PAGO FACTURA HSMC 1221 HYDRA SOLUCIONES EMPRESARIALES INGENIERIA SAS NIT 900437268 POR SERVICIO DEI NTERNERT EN LA AGENCIA DE MOCOA MES DE ENERO 2025 | R2: HPARRA | S2: 2025 | T2: 900437268 | U2: HYDRA SOLUCIONES EMPRESARIALES INGENIERIA SAS
A3: CO | B3: 1000106 | C3: 45679 | D3: 1 | E3: 1 | F3: 999 | G3: Default | J3: 24480502 | K3: Compras | L3: 800102891 | M3: ALCALDIA DE MOCOA | N3: 12436974 | O3: 0 | P3: 62185 | Q3: Contabilización compra dos motocicletas Wave 110s a Maquinagro SA nit 830145805 por valor de $14.800.000 según cotización adjunta y facturasEHK390 - EHK 391 campaña aportes | R3: ANVER | S3: 2025 | T3: 830145805 | U3: MAQUINAGRO S A
A4: CO | B4: 1000121 | C4: 45684 | D4: 1 | E4: 1 | F4: 999 | G4: Default | J4: 24480501 | K4: Servicios | L4: 800102891 | M4: ALCALDIA DE MOCOA | N4: 6594803 | O4: 0 | P4: 65948 | Q4: Contabilización pago fra FVD-1 a Ducardo Jember Urquijo por concepto de servicio Revisoria Fiscal Cootep mes de enero por valor de $6.594.803 | R4: ANVER | S4: 2025 | T4: 18145427 | U4: URQUIJO CHAVEZ DUCARDO JEMBER
A5: CO | B5: 1000129 | C5: 45686 | D5: 1 | E5: 1 | F5: 999 | G5: Default | J5: 24480501 | K5: Servicios | L5: 800102891 | M5: ALCALDIA DE MOCOA | N5: 1170000 | O5: 0 | P5: 11700 | Q5: PAGO DE FACTURA FE9096 A SIGO IPS NIT 900774181 POR EXAMENES DE INGRESO EN LA AGENCIA DE PTO LEGUIZAMO | R5: HPARRA | S5: 2025 | T5: 900774181 | U5: SOLUCIONES INTEGRALES EN GESTION OCUPACIONAL
A6: CO | B6: 1000138 | C6: 45687 | D6: 1 | E6: 1 | F6: 999 | G6: Default | J6: 24480502 | K6: Compras | L6: 800102891 | M6: ALCALDIA DE MOCOA | N6: 595000 | O6: 0 | P6: 2975 | Q6: PAGO A CHAVES ACOSTA YULY FERNANDA CC 1010081868 PORCOMPRA DE PENDONES PARA AREA COMERCIAL | R6: HPARRA | S6: 2025 | T6: 1010081868 | U6: CHAVES ACOSTA YULY FERNANDA
A7: CO | B7: 1000149 | C7: 45691 | D7: 1 | E7: 1 | F7: 999 | G7: Default | J7: 24480501 | K7: Servicios | L7: 800102891 | M7: ALCALDIA DE MOCOA | N7: 480000 | O7: 0 | P7: 4800 | Q7: PAGO FACTURA A HYDRA SOLUCIONES EMPRESARIALES INGENIERIA SAS CC 900437268 POR SERVICIO DE INTERNET AGENCIA MOCOA MES DE FEBRERO 2025 | R7: HPARRA | S7: 2025 | T7: 900437268 | U7: HYDRA SOLUCIONES EMPRESARIALES INGENIERIA SAS
A8: CO | B8: 1000258 | C8: 45699 | D8: 1 | E8: 1 | F8: 999 | G8: Default | J8: 24480502 | K8: Compras | L8: 800102891 | M8: ALCALDIA DE MOCOA | N8: 2095000 | O8: 0 | P8: 12570 | Q8: PAGO FACTURA fev34 a RUIZ GONZALEZ LINSEY MARICEL CC 1124850208 POR COMPRA DE EQUIPOS INSTALADOS EN LA AGENCIA DE COOTEP SIBUNDOY | R8: HPARRA | S8: 2025 | T8: 1124850208 | U8: RUIZ GONZALEZ LINSEY MARICEL
A9: NA | B9: 1000697 | C9: 45712 | D9: 1 | E9: 1 | F9: 999 | G9: Default | J9: 24480501 | K9: Servicios | L9: 800102891 | M9: ALCALDIA DE MOCOA | N9: 1964075 | O9: 0 | P9: 19640 | Q9: PAGO FACTURA FE-651 A ZAMBRANO DUARTE NELSON FABIO CC 18127828 POR SERVICIO DE MONITOREO DE ALARMAS Y CAMARAS DE VIGILANCIA MES FEBRERO 2025 | R9: ANARVA | S9: 2025 | T9: 18127828 | U9: ZAMBRANO DUARTE NELSON FABIO
A10: CO | B10: 1000350 | C10: 45713 | D10: 1 | E10: 1 | F10: 999 | G10: Default | J10: 24480501 | K10: Servicios | L10: 800102891 | M10: ALCALDIA DE MOCOA | N10: 733000 | O10: 0 | P10: 7330 | Q10: LEGALIZACION ANTICIPO ORGANIZACION Y DESARROLLO REUNIONES INFORMATIVAS 2025 | R10: IVAROM | S10: 2025 | T10: 1124853065 | U10: LOZANO CHANCHI FABIERLY JHOANA
A11: CO | B11: 1000383 | C11: 45715 | D11: 1 | E11: 1 | F11: 999 | G11: Default | J11: 24480501 | K11: Servicios | L11: 800102891 | M11: ALCALDIA DE MOCOA | N11: 6594803 | O11: 0 | P11: 65948 | Q11: PAGO FACTURA FVD-2 A URQUIJO CHAVEZ DUCARDO JEMBER NIT 18145427 POR HONORARIOS DE REVISORIA FISCAL COOTEP MES FEBRERO 2025 | R11: ANARVA | S11: 2025 | T11: 18145427 | U11: URQUIJO CHAVEZ DUCARDO JEMBER
A12: CO | B12: 1000505 | C12: 45729 | D12: 1 | E12: 1 | F12: 999 | G12: Default | J12: 24480502 | K12: Compras | L12: 800102891 | M12: ALCALDIA DE MOCOA | N12: 865700 | O12: 0 | P12: 5194 | Q12: PAGO FACTURA FEV36 A RUIZ GONZALEZ LINSEY MARICEL CC 1124850208 POR COMPRA DE EQUIPOS INSTALADOS EN LAS AGENCIAS DE PTO ASIS Y LA DORADA | R12: ANARVA | S12: 2025 | T12: 1124850208 | U12: RUIZ GONZALEZ LINSEY MARICEL
A13: CO | B13: 1000585 | C13: 45744 | D13: 1 | E13: 1 | F13: 999 | G13: Default | J13: 24480501 | K13: Servicios | L13: 800102891 | M13: ALCALDIA DE MOCOA | N13: 720000 | O13: 0 | P13: 7200 | Q13: PAGO DOC SOPOR 1DSE1244 A CHAVES ACOSTA YULY FERNANDA CC 1010081868 POR PRESTACION DE SERVICIOS ELABORACION DE AFICHES Y VOLNATES PARA AREA DE MERCADEO | R13: ANARVA | S13: 2025 | T13: 1010081868 | U13: CHAVES ACOSTA YULY FERNANDA
... A93: CO | B93: 1002977 | C93: 46021 | D93: 1 | E93: 1 | F93: 999 | G93: Default | J93: 24480502 | K93: Compras | L93: 800102891 | M93: ALCALDIA DE MOCOA | N93: 1820350 | O93: 0 | P93: 10922 | Q93: CONTABILIZACION LEGALIZACION ANTICIPO ACTIVIDADES DE FIN DE AÑI COMITE DE SOLIDARIDAD | R93: IVAROM | S93: 2025 | T93: 87680094 | U93: ROSERO ROSERO HUMBERTO JUVENCIO
O95: =SUM(O2:O94) -> 0 | P95: =SUM(P2:P94) -> 1854238

Sheet TERCEROS TODOS
A1: 3-NumeroDeIdentificacion | B1: 4-Dv | C1: 5-PrimerApellido | D1: 6-SegundoApellido | E1: 7-PrimerNombre | F1: 8-OtrosNombres | G1: 9-RazonSocial | H1: 10-Direccion | I1: 11-Departamento | J1: 12-Municipio | K1: 13-Telefono | L1: 14-CorreoElectronico
A2: 6549769 | C2: ROSERO | D2: ORDOÑEZ | E2: JIME | F2: ALEXANDER | H2: #N/A | J2: #N/A | K2: #N/A | L2: #N/A
A3: 10189014 | C3: ARIAS | D3: BETANCUR | E3: JORGE | F3: ALBERTO | H3: #N/A | J3: #N/A | K3: #N/A | L3: #N/A
A4: 12236224 | C4: TOVAR | D4: VALENCIA | E4: JESUS | F4: ANTONIO | H4: #N/A | J4: #N/A | K4: #N/A | L4: #N/A
A5: 12960193 | C5: GUERRA | D5: SANCHEZ | E5: CARLOS | F5: ARTEMIO | H5: #N/A | J5: #N/A | K5: #N/A | L5: #N/A
A6: 12982322 | C6: ZAMBRANO | D6: CORAL | E6: LISIMACO | F6: SALOMON | H6: #N/A | J6: #N/A | K6: #N/A | L6: #N/A
A7: 12997019 | C7: PATIÑO | D7: ALPALA | E7: LUIS | F7: CAMILO | H7: #N/A | J7: #N/A | K7: #N/A | L7: #N/A
A8: 15572024 | C8: ENRIQUEZ | D8: MONTENEGRO | E8: ELKIN | F8: LUGO | H8: #N/A | J8: #N/A | K8: #N/A | L8: #N/A
A9: 16712199 | C9: CEBALLOS | D9: BASTIDAS | E9: HERNAN | F9: VICENTE | H9: #N/A | J9: #N/A | K9: #N/A | L9: #N/A
A10: 17640433 | C10: CHICA | D10: CORDOBA | E10: JAVIER | H10: #N/A | J10: #N/A | K10: #N/A | L10: #N/A
A11: 17655791 | C11: REINOSO | D11: CASTILLO | E11: WILLYE | F11: JAVIER | H11: #N/A | J11: #N/A | K11: #N/A | L11: #N/A
A12: 18103669 | C12: BACCA | D12: ROMO | E12: HECTOR | F12: VICENTE | H12: #N/A | J12: #N/A | K12: #N/A | L12: #N/A
A13: 18125023 | C13: ERAZO | D13: ACOSTA | E13: LUIS | F13: ALEJANDRO | H13: #N/A | J13: #N/A | K13: #N/A | L13: #N/A
A14: 18125303 | C14: GORDILLO | D14: GUZMAN | E14: ALIPIO | H14: #N/A | J14: #N/A | K14: #N/A | L14: #N/A
A15: 18126084 | C15: PANTOJA | D15: ENRIQUE | E15: JAVIER | H15: #N/A | J15: #N/A | K15: #N/A | L15: #N/A
A16: 18127030 | C16: ROSERO | D16: MONCAYO | E16: YESID | F16: BERNARDO | H16: #N/A | J16: #N/A | K16: #N/A | L16: #N/A
A17: 18127050 | C17: MUÑOZ | D17: CERON | E17: GIOVANNY | H17: #N/A | J17: #N/A | K17: #N/A | L17: #N/A
A18: 18130206 | C18: PORTILLA | D18: CERON | E18: JAIME | H18: #N/A | J18: #N/A | K18: #N/A | L18: #N/A
A19: 18144083 | C19: ROSERO | D19: GALINDEZ | E19: ARTURO | H19: #N/A | J19: #N/A | K19: #N/A | L19: #N/A
A20: 18144169 | C20: MORIANO | D20: VIVEROS | E20: YINGUER | F20: MARCELO | H20: #N/A | J20: #N/A | K20: #N/A | L20: #N/A
A21: 18145427 | C21: URQUIJO | D21: CHAVEZ | E21: DUCARDO | F21: JEMBER | H21: #N/A | J21: #N/A | K21: #N/A | L21: #N/A
A22: 18155317 | C22: NASTACUAS | D22: CUARAN | E22: MILTON | F22: JAVIER | H22: #N/A | J22: #N/A | K22: #N/A | L22: #N/A
A23: 18184893 | C23: POLANIA | D23: ROJAS | E23: WILLIAM | H23: #N/A | J23: #N/A | K23: #N/A | L23: #N/A
A24: 19199527 | C24: GARZON | D24: JIMENEZ | E24: HIPOLITO | H24: #N/A | J24: #N/A | K24: #N/A | L24: #N/A
A25: 26636874 | C25: SANCHEZ | D25: GONZALEZ | E25: MARIA | F25: INES | H25: #N/A | J25: #N/A | K25: #N/A | L25: #N/A
A26: 27474915 | C26: SANDOVAL | D26: MALLAMA | E26: RUDH | F26: DEL | G26: PILAR | H26: #N/A | J26: #N/A | K26: #N/A | L26: #N/A
A27: 40076819 | C27: SOTO | D27: ARANDA | E27: MARIA | F27: LUISA | H27: #N/A | J27: #N/A | K27: #N/A | L27: #N/A
A28: 41101376 | C28: ZAMBRANO | D28: MARIA | E28: ELVIA | H28: #N/A | J28: #N/A | K28: #N/A | L28: #N/A
A29: 41103850 | C29: GUINCHIN | D29: ESTRADA | E29: ALBA | F29: NORY | H29: #N/A | J29: #N/A | K29: #N/A | L29: #N/A
A30: 41108005 | C30: RUALES | D30: RUALES | E30: RUTH | F30: JANETH | H30: #N/A | J30: #N/A | K30: #N/A | L30: #N/A
A31: 41116311 | C31: PASCAL | D31: GUANGA | E31: NELLY | H31: #N/A | J31: #N/A | K31: #N/A | L31: #N/A
A32: 41117737 | C32: CUACES | D32: ZAMBRANO | E32: DORIS | F32: ALICIA | H32: #N/A | J32: #N/A | K32: #N/A | L32: #N/A
A33: 41170105 | C33: DIAZ | D33: MOLINA | E33: ARACELY | H33: #N/A | J33: #N/A | K33: #N/A | L33: #N/A
A34: 41170646 | C34: MUÑOZ | D34: GUERRERO | E34: MARY | F34: LUZ | H34: #N/A | J34: #N/A | K34: #N/A | L34: #N/A
A35: 41181552 | C35: CEBALLOS | D35: MEJIA | E35: RUTH | F35: HAYLEN | H35: #N/A | J35: #N/A | K35: #N/A | L35: #N/A
A36: 41181655 | C36: ESPANA | D36: BURBANO | E36: NOHORA | F36: ZORAIDA | H36: #N/A | J36: #N/A | K36: #N/A | L36: #N/A
A37: 48600248 | C37: ALVAREZ | D37: CAYCEDO | E37: MARTHA | F37: LUCIA | H37: #N/A | J37: #N/A | K37: #N/A | L37: #N/A
A38: 52952416 | C38: GONZALEZ | D38: GONZALEZ | E38: YURIBIA | H38: #N/A | J38: #N/A | K38: #N/A | L38: #N/A
A39: 52969434 | C39: BOLIVAR | D39: REYES | E39: ERIKA | F39: YALLINNE | H39: #N/A | J39: #N/A | K39: #N/A | L39: #N/A
A40: 53051826 | C40: LOPEZ | D40: CARMONA | E40: BIBIANA | F40: YANET | H40: #N/A | J40: #N/A | K40: #N/A | L40: #N/A
...
